Workbook

Sheet Sheet1
A1: raw text input | B1: dataType | C1: wireName | F1: capitalized wire name | G1: column name | H1: column code | J1: eventsTableHelper
A2: [TenantId] as tenantId | B2: TEXT | C2: =SUBSTITUTE(TRIM(RIGHT(SUBSTITUTE(A2," ",REPT(" ",100)),100)),",","") -> tenantId | D2: ="this."&C2 & "," -> this.tenantId, | E2: ="final " & VLOOKUP(B2,Sheet2!$A$1:$B$4,2,FALSE) & " " & C2 & ";" -> final String tenantId; | F2: =UPPER(MID(C2,1,1)) & MID(C2,2,9999) -> TenantId | G2: ="col"&F2 -> colTenantId | H2: ="final String "&G2&"= '"&C2&"';" -> final String colTenantId= 'tenantId'; | I2: ="$"&G2&" "&B2&"," -> $colTenantId TEXT, | J2: ="ALTER TABLE ${"&$J$1&".tableName} ADD COLUMN ${"&$J$1&"."&G2&"} "&B2&";" -> ALTER TABLE ${eventsTableHelper.tableName} ADD COLUMN ${eventsTableHelper.colTenantId} TEXT;
A3: ,[FacilityId] as facilityId | B3: TEXT | C3: =SUBSTITUTE(TRIM(RIGHT(SUBSTITUTE(A3," ",REPT(" ",100)),100)),",","") -> facilityId | D3: ="this."&C3 & "," -> this.facilityId, | E3: ="final " & VLOOKUP(B3,Sheet2!$A$1:$B$4,2,FALSE) & " " & C3 & ";" -> final String facilityId; | F3: =UPPER(MID(C3,1,1)) & MID(C3,2,9999) -> FacilityId | G3: ="col"&F3 -> colFacilityId | H3: ="final String "&G3&"= '"&C3&"';" -> final String colFacilityId= 'facilityId'; | I3: ="$"&G3&" "&B3&"," -> $colFacilityId TEXT, | J3: ="ALTER TABLE ${"&$J$1&".tableName} ADD COLUMN ${"&$J$1&"."&G3&"} "&B3&";" -> ALTER TABLE ${eventsTableHelper.tableName} ADD COLUMN ${eventsTableHelper.colFacilityId} TEXT;
A4: ,[FacilityCode] as facilityCode | B4: TEXT | C4: =SUBSTITUTE(TRIM(RIGHT(SUBSTITUTE(A4," ",REPT(" ",100)),100)),",","") -> facilityCode | D4: ="this."&C4 & "," -> this.facilityCode, | E4: ="final " & VLOOKUP(B4,Sheet2!$A$1:$B$4,2,FALSE) & " " & C4 & ";" -> final String facilityCode; | F4: =UPPER(MID(C4,1,1)) & MID(C4,2,9999) -> FacilityCode | G4: ="col"&F4 -> colFacilityCode | H4: ="final String "&G4&"= '"&C4&"';" -> final String colFacilityCode= 'facilityCode'; | I4: ="$"&G4&" "&B4&"," -> $colFacilityCode TEXT, | J4: ="ALTER TABLE ${"&$J$1&".tableName} ADD COLUMN ${"&$J$1&"."&G4&"} "&B4&";" -> ALTER TABLE ${eventsTableHelper.tableName} ADD COLUMN ${eventsTableHelper.colFacilityCode} TEXT;
A5: ,[FacilityName] as facilityName | B5: TEXT | C5: =SUBSTITUTE(TRIM(RIGHT(SUBSTITUTE(A5," ",REPT(" ",100)),100)),",","") -> facilityName | D5: ="this."&C5 & "," -> this.facilityName, | E5: ="final " & VLOOKUP(B5,Sheet2!$A$1:$B$4,2,FALSE) & " " & C5 & ";" -> final String facilityName; | F5: =UPPER(MID(C5,1,1)) & MID(C5,2,9999) -> FacilityName | G5: ="col"&F5 -> colFacilityName | H5: ="final String "&G5&"= '"&C5&"';" -> final String colFacilityName= 'facilityName'; | I5: ="$"&G5&" "&B5&"," -> $colFacilityName TEXT, | J5: ="ALTER TABLE ${"&$J$1&".tableName} ADD COLUMN ${"&$J$1&"."&G5&"} "&B5&";" -> ALTER TABLE ${eventsTableHelper.tableName} ADD COLUMN ${eventsTableHelper.colFacilityName} TEXT;
A6: ,[isActive] as isActive | B6: INT | C6: =SUBSTITUTE(TRIM(RIGHT(SUBSTITUTE(A6," ",REPT(" ",100)),100)),",","") -> isActive | D6: ="this."&C6 & "," -> this.isActive, | E6: ="final " & VLOOKUP(B6,Sheet2!$A$1:$B$4,2,FALSE) & " " & C6 & ";" -> final int isActive; | F6: =UPPER(MID(C6,1,1)) & MID(C6,2,9999) -> IsActive | G6: ="col"&F6 -> colIsActive | H6: ="final String "&G6&"= '"&C6&"';" -> final String colIsActive= 'isActive'; | I6: ="$"&G6&" "&B6&"," -> $colIsActive INT, | J6: ="ALTER TABLE ${"&$J$1&".tableName} ADD COLUMN ${"&$J$1&"."&G6&"} "&B6&";" -> ALTER TABLE ${eventsTableHelper.tableName} ADD COLUMN ${eventsTableHelper.colIsActive} INT;
C7: =SUBSTITUTE(TRIM(RIGHT(SUBSTITUTE(A7," ",REPT(" ",100)),100)),",","") | D7: ="this."&C7 & "," -> this., | E7: ="final " & VLOOKUP(B7,Sheet2!$A$1:$B$4,2,FALSE) & " " & C7 & ";" -> #N/A | F7: =UPPER(MID(C7,1,1)) & MID(C7,2,9999) | G7: ="col"&F7 -> col | H7: ="final String "&G7&"= '"&C7&"';" -> final String col= ''; | I7: ="$"&G7&" "&B7&"," -> $col , | J7: ="ALTER TABLE ${"&$J$1&".tableName} ADD COLUMN ${"&$J$1&"."&G7&"} "&B7&";" -> ALTER TABLE ${eventsTableHelper.tableName} ADD COLUMN ${eventsTableHelper.col} ;
A8: [TenantId] as tenantId | B8: TEXT | C8: =SUBSTITUTE(TRIM(RIGHT(SUBSTITUTE(A8," ",REPT(" ",100)),100)),",","") -> tenantId | D8: ="this."&C8 & "," -> this.tenantId, | E8: ="final " & VLOOKUP(B8,Sheet2!$A$1:$B$4,2,FALSE) & " " & C8 & ";" -> final String tenantId; | F8: =UPPER(MID(C8,1,1)) & MID(C8,2,9999) -> TenantId | G8: ="col"&F8 -> colTenantId | H8: ="final String "&G8&"= '"&C8&"';" -> final String colTenantId= 'tenantId'; | I8: ="$"&G8&" "&B8&"," -> $colTenantId TEXT, | J8: ="ALTER TABLE ${"&$J$1&".tableName} ADD COLUMN ${"&$J$1&"."&G8&"} "&B8&";" -> ALTER TABLE ${eventsTableHelper.tableName} ADD COLUMN ${eventsTableHelper.colTenantId} TEXT;
A9: ,[BuildingId] as buildingId | B9: TEXT | C9: =SUBSTITUTE(TRIM(RIGHT(SUBSTITUTE(A9," ",REPT(" ",100)),100)),",","") -> buildingId | D9: ="this."&C9 & "," -> this.buildingId, | E9: ="final " & VLOOKUP(B9,Sheet2!$A$1:$B$4,2,FALSE) & " " & C9 & ";" -> final String buildingId; | F9: =UPPER(MID(C9,1,1)) & MID(C9,2,9999) -> BuildingId | G9: ="col"&F9 -> colBuildingId | H9: ="final String "&G9&"= '"&C9&"';" -> final String colBuildingId= 'buildingId'; | I9: ="$"&G9&" "&B9&"," -> $colBuildingId TEXT, | J9: ="ALTER TABLE ${"&$J$1&".tableName} ADD COLUMN ${"&$J$1&"."&G9&"} "&B9&";" -> ALTER TABLE ${eventsTableHelper.tableName} ADD COLUMN ${eventsTableHelper.colBuildingId} TEXT;
A10: ,[FacilityId] as facilityId | B10: TEXT | C10: =SUBSTITUTE(TRIM(RIGHT(SUBSTITUTE(A10," ",REPT(" ",100)),100)),",","") -> facilityId | D10: ="this."&C10 & "," -> this.facilityId, | E10: ="final " & VLOOKUP(B10,Sheet2!$A$1:$B$4,2,FALSE) & " " & C10 & ";" -> final String facilityId; | F10: =UPPER(MID(C10,1,1)) & MID(C10,2,9999) -> FacilityId | G10: ="col"&F10 -> colFacilityId | H10: ="final String "&G10&"= '"&C10&"';" -> final String colFacilityId= 'facilityId'; | I10: ="$"&G10&" "&B10&"," -> $colFacilityId TEXT, | J10: ="ALTER TABLE ${"&$J$1&".tableName} ADD COLUMN ${"&$J$1&"."&G10&"} "&B10&";" -> ALTER TABLE ${eventsTableHelper.tableName} ADD COLUMN ${eventsTableHelper.colFacilityId} TEXT;
A11: ,[BuildingName] as buildingName | B11: TEXT | C11: =SUBSTITUTE(TRIM(RIGHT(SUBSTITUTE(A11," ",REPT(" ",100)),100)),",","") -> buildingName | D11: ="this."&C11 & "," -> this.buildingName, | E11: ="final " & VLOOKUP(B11,Sheet2!$A$1:$B$4,2,FALSE) & " " & C11 & ";" -> final String buildingName; | F11: =UPPER(MID(C11,1,1)) & MID(C11,2,9999) -> BuildingName | G11: ="col"&F11 -> colBuildingName | H11: ="final String "&G11&"= '"&C11&"';" -> final String colBuildingName= 'buildingName'; | I11: ="$"&G11&" "&B11&"," -> $colBuildingName TEXT, | J11: ="ALTER TABLE ${"&$J$1&".tableName} ADD COLUMN ${"&$J$1&"."&G11&"} "&B11&";" -> ALTER TABLE ${eventsTableHelper.tableName} ADD COLUMN ${eventsTableHelper.colBuildingName} TEXT;
A12: ,[BuildingCode] as buildingCode | B12: TEXT | C12: =SUBSTITUTE(TRIM(RIGHT(SUBSTITUTE(A12," ",REPT(" ",100)),100)),",","") -> buildingCode | D12: ="this."&C12 & "," -> this.buildingCode, | E12: ="final " & VLOOKUP(B12,Sheet2!$A$1:$B$4,2,FALSE) & " " & C12 & ";" -> final String buildingCode; | F12: =UPPER(MID(C12,1,1)) & MID(C12,2,9999) -> BuildingCode | G12: ="col"&F12 -> colBuildingCode | H12: ="final String "&G12&"= '"&C12&"';" -> final String colBuildingCode= 'buildingCode'; | I12: ="$"&G12&" "&B12&"," -> $colBuildingCode TEXT, | J12: ="ALTER TABLE ${"&$J$1&".tableName} ADD COLUMN ${"&$J$1&"."&G12&"} "&B12&";" -> ALTER TABLE ${eventsTableHelper.tableName} ADD COLUMN ${eventsTableHelper.colBuildingCode} TEXT;
A13: ,[isNoZone] as isNoZone | B13: INT | C13: =SUBSTITUTE(TRIM(RIGHT(SUBSTITUTE(A13," ",REPT(" ",100)),100)),",","") -> isNoZone | D13: ="this."&C13 & "," -> this.isNoZone, | E13: ="final " & VLOOKUP(B13,Sheet2!$A$1:$B$4,2,FALSE) & " " & C13 & ";" -> final int isNoZone; | F13: =UPPER(MID(C13,1,1)) & MID(C13,2,9999) -> IsNoZone | G13: ="col"&F13 -> colIsNoZone | H13: ="final String "&G13&"= '"&C13&"';" -> final String colIsNoZone= 'isNoZone'; | I13: ="$"&G13&" "&B13&"," -> $colIsNoZone INT, | J13: ="ALTER TABLE ${"&$J$1&".tableName} ADD COLUMN ${"&$J$1&"."&G13&"} "&B13&";" -> ALTER TABLE ${eventsTableHelper.tableName} ADD COLUMN ${eventsTableHelper.colIsNoZone} INT;
A14: ,[isActive] as isActive | B14: INT | C14: =SUBSTITUTE(TRIM(RIGHT(SUBSTITUTE(A14," ",REPT(" ",100)),100)),",","") -> isActive | D14: ="this."&C14 & "," -> this.isActive, | E14: ="final " & VLOOKUP(B14,Sheet2!$A$1:$B$4,2,FALSE) & " " & C14 & ";" -> final int isActive; | F14: =UPPER(MID(C14,1,1)) & MID(C14,2,9999) -> IsActive | G14: ="col"&F14 -> colIsActive | H14: ="final String "&G14&"= '"&C14&"';" -> final String colIsActive= 'isActive'; | I14: ="$"&G14&" "&B14&"," -> $colIsActive INT, | J14: ="ALTER TABLE ${"&$J$1&".tableName} ADD COLUMN ${"&$J$1&"."&G14&"} "&B14&";" -> ALTER TABLE ${eventsTableHelper.tableName} ADD COLUMN ${eventsTableHelper.colIsActive} INT;
C15: =SUBSTITUTE(TRIM(RIGHT(SUBSTITUTE(A15," ",REPT(" ",100)),100)),",","") | D15: ="this."&C15 & "," -> this., | E15: ="final " & VLOOKUP(B15,Sheet2!$A$1:$B$4,2,FALSE) & " " & C15 & ";" -> #N/A | F15: =UPPER(MID(C15,1,1)) & MID(C15,2,9999) | G15: ="col"&F15 -> col | H15: ="final String "&G15&"= '"&C15&"';" -> final String col= ''; | I15: ="$"&G15&" "&B15&"," -> $col , | J15: ="ALTER TABLE ${"&$J$1&".tableName} ADD COLUMN ${"&$J$1&"."&G15&"} "&B15&";" -> ALTER TABLE ${eventsTableHelper.tableName} ADD COLUMN ${eventsTableHelper.col} ;
A16: [TenantId] as tenantId | B16: TEXT | C16: =SUBSTITUTE(TRIM(RIGHT(SUBSTITUTE(A16," ",REPT(" ",100)),100)),",","") -> tenantId | D16: ="this."&C16 & "," -> this.tenantId, | E16: ="final " & VLOOKUP(B16,Sheet2!$A$1:$B$4,2,FALSE) & " " & C16 & ";" -> final String tenantId; | F16: =UPPER(MID(C16,1,1)) & MID(C16,2,9999) -> TenantId | G16: ="col"&F16 -> colTenantId | H16: ="final String "&G16&"= '"&C16&"';" -> final String colTenantId= 'tenantId'; | I16: ="$"&G16&" "&B16&"," -> $colTenantId TEXT, | J16: ="ALTER TABLE ${"&$J$1&".tableName} ADD COLUMN ${"&$J$1&"."&G16&"} "&B16&";" -> ALTER TABLE ${eventsTableHelper.tableName} ADD COLUMN ${eventsTableHelper.colTenantId} TEXT;
A17: ,[RoomId] as roomId | B17: TEXT | C17: =SUBSTITUTE(TRIM(RIGHT(SUBSTITUTE(A17," ",REPT(" ",100)),100)),",","") -> roomId | D17: ="this."&C17 & "," -> this.roomId, | E17: ="final " & VLOOKUP(B17,Sheet2!$A$1:$B$4,2,FALSE) & " " & C17 & ";" -> final String roomId; | F17: =UPPER(MID(C17,1,1)) & MID(C17,2,9999) -> RoomId | G17: ="col"&F17 -> colRoomId | H17: ="final String "&G17&"= '"&C17&"';" -> final String colRoomId= 'roomId'; | I17: ="$"&G17&" "&B17&"," -> $colRoomId TEXT, | J17: ="ALTER TABLE ${"&$J$1&".tableName} ADD COLUMN ${"&$J$1&"."&G17&"} "&B17&";" -> ALTER TABLE ${eventsTableHelper.tableName} ADD COLUMN ${eventsTableHelper.colRoomId} TEXT;
A18: ,[BuildingId] as buildingId | B18: TEXT | C18: =SUBSTITUTE(TRIM(RIGHT(SUBSTITUTE(A18," ",REPT(" ",100)),100)),",","") -> buildingId | D18: ="this."&C18 & "," -> this.buildingId, | E18: ="final " & VLOOKUP(B18,Sheet2!$A$1:$B$4,2,FALSE) & " " & C18 & ";" -> final String buildingId; | F18: =UPPER(MID(C18,1,1)) & MID(C18,2,9999) -> BuildingId | G18: ="col"&F18 -> colBuildingId | H18: ="final String "&G18&"= '"&C18&"';" -> final String colBuildingId= 'buildingId'; | I18: ="$"&G18&" "&B18&"," -> $colBuildingId TEXT, | J18: ="ALTER TABLE ${"&$J$1&".tableName} ADD COLUMN ${"&$J$1&"."&G18&"} "&B18&";" -> ALTER TABLE ${eventsTableHelper.tableName} ADD COLUMN ${eventsTableHelper.colBuildingId} TEXT;
A19: ,[RoomName] as roomName | B19: TEXT | C19: =SUBSTITUTE(TRIM(RIGHT(SUBSTITUTE(A19," ",REPT(" ",100)),100)),",","") -> roomName | D19: ="this."&C19 & "," -> this.roomName, | E19: ="final " & VLOOKUP(B19,Sheet2!$A$1:$B$4,2,FALSE) & " " & C19 & ";" -> final String roomName; | F19: =UPPER(MID(C19,1,1)) & MID(C19,2,9999) -> RoomName | G19: ="col"&F19 -> colRoomName | H19: ="final String "&G19&"= '"&C19&"';" -> final String colRoomName= 'roomName'; | I19: ="$"&G19&" "&B19&"," -> $colRoomName TEXT, | J19: ="ALTER TABLE ${"&$J$1&".tableName} ADD COLUMN ${"&$J$1&"."&G19&"} "&B19&";" -> ALTER TABLE ${eventsTableHelper.tableName} ADD COLUMN ${eventsTableHelper.colRoomName} TEXT;
A20: ,[QrCode] as qrCode | B20: TEXT | C20: =SUBSTITUTE(TRIM(RIGHT(SUBSTITUTE(A20," ",REPT(" ",100)),100)),",","") -> qrCode | D20: ="this."&C20 & "," -> this.qrCode, | E20: ="final " & VLOOKUP(B20,Sheet2!$A$1:$B$4,2,FALSE) & " " & C20 & ";" -> final String qrCode; | F20: =UPPER(MID(C20,1,1)) & MID(C20,2,9999) -> QrCode | G20: ="col"&F20 -> colQrCode | H20: ="final String "&G20&"= '"&C20&"';" -> final String colQrCode= 'qrCode'; | I20: ="$"&G20&" "&B20&"," -> $colQrCode TEXT, | J20: ="ALTER TABLE ${"&$J$1&".tableName} ADD COLUMN ${"&$J$1&"."&G20&"} "&B20&";" -> ALTER TABLE ${eventsTableHelper.tableName} ADD COLUMN ${eventsTableHelper.colQrCode} TEXT;
A21: ,[Occupancy] as occupancy | B21: INT | C21: =SUBSTITUTE(TRIM(RIGHT(SUBSTITUTE(A21," ",REPT(" ",100)),100)),",","") -> occupancy | D21: ="this."&C21 & "," -> this.occupancy, | E21: ="final " & VLOOKUP(B21,Sheet2!$A$1:$B$4,2,FALSE) & " " & C21 & ";" -> final int occupancy; | F21: =UPPER(MID(C21,1,1)) & MID(C21,2,9999) -> Occupancy | G21: ="col"&F21 -> colOccupancy | H21: ="final String "&G21&"= '"&C21&"';" -> final String colOccupancy= 'occupancy'; | I21: ="$"&G21&" "&B21&"," -> $colOccupancy INT, | J21: ="ALTER TABLE ${"&$J$1&".tableName} ADD COLUMN ${"&$J$1&"."&G21&"} "&B21&";" -> ALTER TABLE ${eventsTableHelper.tableName} ADD COLUMN ${eventsTableHelper.colOccupancy} INT;
A22: ,[RoomType] as roomType | B22: INT | C22: =SUBSTITUTE(TRIM(RIGHT(SUBSTITUTE(A22," ",REPT(" ",100)),100)),",","") -> roomType | D22: ="this."&C22 & "," -> this.roomType, | E22: ="final " & VLOOKUP(B22,Sheet2!$A$1:$B$4,2,FALSE) & " " & C22 & ";" -> final int roomType; | F22: =UPPER(MID(C22,1,1)) & MID(C22,2,9999) -> RoomType | G22: ="col"&F22 -> colRoomType | H22: ="final String "&G22&"= '"&C22&"';" -> final String colRoomType= 'roomType'; | I22: ="$"&G22&" "&B22&"," -> $colRoomType INT, | J22: ="ALTER TABLE ${"&$J$1&".tableName} ADD COLUMN ${"&$J$1&"."&G22&"} "&B22&";" -> ALTER TABLE ${eventsTableHelper.tableName} ADD COLUMN ${eventsTableHelper.colRoomType} INT;
A23: ,[Floor] as floor | B23: INT | C23: =SUBSTITUTE(TRIM(RIGHT(SUBSTITUTE(A23," ",REPT(" ",100)),100)),",","") -> floor | D23: ="this."&C23 & "," -> this.floor, | E23: ="final " & VLOOKUP(B23,Sheet2!$A$1:$B$4,2,FALSE) & " " & C23 & ";" -> final int floor; | F23: =UPPER(MID(C23,1,1)) & MID(C23,2,9999) -> Floor | G23: ="col"&F23 -> colFloor | H23: ="final String "&G23&"= '"&C23&"';" -> final String colFloor= 'floor'; | I23: ="$"&G23&" "&B23&"," -> $colFloor INT, | J23: ="ALTER TABLE ${"&$J$1&".tableName} ADD COLUMN ${"&$J$1&"."&G23&"} "&B23&";" -> ALTER TABLE ${eventsTableHelper.tableName} ADD COLUMN ${eventsTableHelper.colFloor} INT;
A24: ,[SecurityLevel] as securityLevel | B24: INT | C24: =SUBSTITUTE(TRIM(RIGHT(SUBSTITUTE(A24," ",REPT(" ",100)),100)),",","") -> securityLevel | D24: ="this."&C24 & "," -> this.securityLevel, | E24: ="final " & VLOOKUP(B24,Sheet2!$A$1:$B$4,2,FALSE) & " " & C24 & ";" -> final int securityLevel; | F24: =UPPER(MID(C24,1,1)) & MID(C24,2,9999) -> SecurityLevel | G24: ="col"&F24 -> colSecurityLevel | H24: ="final String "&G24&"= '"&C24&"';" -> final String colSecurityLevel= 'securityLevel'; | I24: ="$"&G24&" "&B24&"," -> $colSecurityLevel INT, | J24: ="ALTER TABLE ${"&$J$1&".tableName} ADD COLUMN ${"&$J$1&"."&G24&"} "&B24&";" -> ALTER TABLE ${eventsTableHelper.tableName} ADD COLUMN ${eventsTableHelper.colSecurityLevel} INT;
A25: ,[RiskFactor] as riskFactor | B25: NUM | C25: =SUBSTITUTE(TRIM(RIGHT(SUBSTITUTE(A25," ",REPT(" ",100)),100)),",","") -> riskFactor | D25: ="this."&C25 & "," -> this.riskFactor, | E25: ="final " & VLOOKUP(B25,Sheet2!$A$1:$B$4,2,FALSE) & " " & C25 & ";" -> final num riskFactor; | F25: =UPPER(MID(C25,1,1)) & MID(C25,2,9999) -> RiskFactor | G25: ="col"&F25 -> colRiskFactor | H25: ="final String "&G25&"= '"&C25&"';" -> final String colRiskFactor= 'riskFactor'; | I25: ="$"&G25&" "&B25&"," -> $colRiskFactor NUM, | J25: ="ALTER TABLE ${"&$J$1&".tableName} ADD COLUMN ${"&$J$1&"."&G25&"} "&B25&";" -> ALTER TABLE ${eventsTableHelper.tableName} ADD COLUMN ${eventsTableHelper.colRiskFactor} NUM;
A26: ,[Lat] as lat | B26: NUM | C26: =SUBSTITUTE(TRIM(RIGHT(SUBSTITUTE(A26," ",REPT(" ",100)),100)),",","") -> lat | D26: ="this."&C26 & "," -> this.lat, | E26: ="final " & VLOOKUP(B26,Sheet2!$A$1:$B$4,2,FALSE) & " " & C26 & ";" -> final num lat; | F26: =UPPER(MID(C26,1,1)) & MID(C26,2,9999) -> Lat | G26: ="col"&F26 -> colLat | H26: ="final String "&G26&"= '"&C26&"';" -> final String colLat= 'lat'; | I26: ="$"&G26&" "&B26&"," -> $colLat NUM, | J26: ="ALTER TABLE ${"&$J$1&".tableName} ADD COLUMN ${"&$J$1&"."&G26&"} "&B26&";" -> ALTER TABLE ${eventsTableHelper.tableName} ADD COLUMN ${eventsTableHelper.colLat} NUM;
A27: ,[Lon] as lon | B27: NUM | C27: =SUBSTITUTE(TRIM(RIGHT(SUBSTITUTE(A27," ",REPT(" ",100)),100)),",","") -> lon | D27: ="this."&C27 & "," -> this.lon, | E27: ="final " & VLOOKUP(B27,Sheet2!$A$1:$B$4,2,FALSE) & " " & C27 & ";" -> final num lon; | F27: =UPPER(MID(C27,1,1)) & MID(C27,2,9999) -> Lon | G27: ="col"&F27 -> colLon | H27: ="final String "&G27&"= '"&C27&"';" -> final String colLon= 'lon'; | I27: ="$"&G27&" "&B27&"," -> $colLon NUM, | J27: ="ALTER TABLE ${"&$J$1&".tableName} ADD COLUMN ${"&$J$1&"."&G27&"} "&B27&";" -> ALTER TABLE ${eventsTableHelper.tableName} ADD COLUMN ${eventsTableHelper.colLon} NUM;
... A35: ,[isActive] as isActive | B35: INT | C35: =SUBSTITUTE(TRIM(RIGHT(SUBSTITUTE(A35," ",REPT(" ",100)),100)),",","") -> isActive | D35: ="this."&C35 & "," -> this.isActive, | E35: ="final " & VLOOKUP(B35,Sheet2!$A$1:$B$4,2,FALSE) & " " & C35 & ";" -> final int isActive; | F35: =UPPER(MID(C35,1,1)) & MID(C35,2,9999) -> IsActive | G35: ="col"&F35 -> colIsActive | H35: ="final String "&G35&"= '"&C35&"';" -> final String colIsActive= 'isActive'; | I35: ="$"&G35&" "&B35&"," -> $colIsActive INT, | J35: ="ALTER TABLE ${"&$J$1&".tableName} ADD COLUMN ${"&$J$1&"."&G35&"} "&B35&";" -> ALTER TABLE ${eventsTableHelper.tableName} ADD COLUMN ${eventsTableHelper.colIsActive} INT;
C36: =SUBSTITUTE(TRIM(RIGHT(SUBSTITUTE(A36," ",REPT(" ",100)),100)),",","") | D36: ="this."&C36 & "," -> this., | E36: ="final " & VLOOKUP(B36,Sheet2!$A$1:$B$4,2,FALSE) & " " & C36 & ";" -> #N/A | F36: =UPPER(MID(C36,1,1)) & MID(C36,2,9999) | G36: ="col"&F36 -> col | H36: ="final String "&G36&"= '"&C36&"';" -> final String col= ''; | I36: ="$"&G36&" "&B36&"," -> $col , | J36: ="ALTER TABLE ${"&$J$1&".tableName} ADD COLUMN ${"&$J$1&"."&G36&"} "&B36&";" -> ALTER TABLE ${eventsTableHelper.tableName} ADD COLUMN ${eventsTableHelper.col} ;
A37: [TenantId] as tenantId | B37: TEXT | C37: =SUBSTITUTE(TRIM(RIGHT(SUBSTITUTE(A37," ",REPT(" ",100)),100)),",","") -> tenantId | D37: ="this."&C37 & "," -> this.tenantId, | E37: ="final " & VLOOKUP(B37,Sheet2!$A$1:$B$4,2,FALSE) & " " & C37 & ";" -> final String tenantId; | F37: =UPPER(MID(C37,1,1)) & MID(C37,2,9999) -> TenantId | G37: ="col"&F37 -> colTenantId | H37: ="final String "&G37&"= '"&C37&"';" -> final String colTenantId= 'tenantId'; | I37: ="$"&G37&" "&B37&"," -> $colTenantId TEXT, | J37: ="ALTER TABLE ${"&$J$1&".tableName} ADD COLUMN ${"&$J$1&"."&G37&"} "&B37&";" -> ALTER TABLE ${eventsTableHelper.tableName} ADD COLUMN ${eventsTableHelper.colTenantId} TEXT;
A38: ,[PointId] as tapPointId | B38: TEXT | C38: =SUBSTITUTE(TRIM(RIGHT(SUBSTITUTE(A38," ",REPT(" ",100)),100)),",","") -> tapPointId | D38: ="this."&C38 & "," -> this.tapPointId, | E38: ="final " & VLOOKUP(B38,Sheet2!$A$1:$B$4,2,FALSE) & " " & C38 & ";" -> final String tapPointId; | F38: =UPPER(MID(C38,1,1)) & MID(C38,2,9999) -> TapPointId | G38: ="col"&F38 -> colTapPointId | H38: ="final String "&G38&"= '"&C38&"';" -> final String colTapPointId= 'tapPointId'; | I38: ="$"&G38&" "&B38&"," -> $colTapPointId TEXT, | J38: ="ALTER TABLE ${"&$J$1&".tableName} ADD COLUMN ${"&$J$1&"."&G38&"} "&B38&";" -> ALTER TABLE ${eventsTableHelper.tableName} ADD COLUMN ${eventsTableHelper.colTapPointId} TEXT;
A39: ,[RoomId] as roomId | B39: TEXT | C39: =SUBSTITUTE(TRIM(RIGHT(SUBSTITUTE(A39," ",REPT(" ",100)),100)),",","") -> roomId | D39: ="this."&C39 & "," -> this.roomId, | E39: ="final " & VLOOKUP(B39,Sheet2!$A$1:$B$4,2,FALSE) & " " & C39 & ";" -> final String roomId; | F39: =UPPER(MID(C39,1,1)) & MID(C39,2,9999) -> RoomId | G39: ="col"&F39 -> colRoomId | H39: ="final String "&G39&"= '"&C39&"';" -> final String colRoomId= 'roomId'; | I39: ="$"&G39&" "&B39&"," -> $colRoomId TEXT, | J39: ="ALTER TABLE ${"&$J$1&".tableName} ADD COLUMN ${"&$J$1&"."&G39&"} "&B39&";" -> ALTER TABLE ${eventsTableHelper.tableName} ADD COLUMN ${eventsTableHelper.colRoomId} TEXT;
A40: ,[PointName] as pointName | B40: TEXT | C40: =SUBSTITUTE(TRIM(RIGHT(SUBSTITUTE(A40," ",REPT(" ",100)),100)),",","") -> pointName | D40: ="this."&C40 & "," -> this.pointName, | E40: ="final " & VLOOKUP(B40,Sheet2!$A$1:$B$4,2,FALSE) & " " & C40 & ";" -> final String pointName; | F40: =UPPER(MID(C40,1,1)) & MID(C40,2,9999) -> PointName | G40: ="col"&F40 -> colPointName | H40: ="final String "&G40&"= '"&C40&"';" -> final String colPointName= 'pointName'; | I40: ="$"&G40&" "&B40&"," -> $colPointName TEXT, | J40: ="ALTER TABLE ${"&$J$1&".tableName} ADD COLUMN ${"&$J$1&"."&G40&"} "&B40&";" -> ALTER TABLE ${eventsTableHelper.tableName} ADD COLUMN ${eventsTableHelper.colPointName} TEXT;
A41: ,[QrCode] as qrCode | B41: TEXT | C41: =SUBSTITUTE(TRIM(RIGHT(SUBSTITUTE(A41," ",REPT(" ",100)),100)),",","") -> qrCode | D41: ="this."&C41 & "," -> this.qrCode, | E41: ="final " & VLOOKUP(B41,Sheet2!$A$1:$B$4,2,FALSE) & " " & C41 & ";" -> final String qrCode; | F41: =UPPER(MID(C41,1,1)) & MID(C41,2,9999) -> QrCode | G41: ="col"&F41 -> colQrCode | H41: ="final String "&G41&"= '"&C41&"';" -> final String colQrCode= 'qrCode'; | I41: ="$"&G41&" "&B41&"," -> $colQrCode TEXT, | J41: ="ALTER TABLE ${"&$J$1&".tableName} ADD COLUMN ${"&$J$1&"."&G41&"} "&B41&";" -> ALTER TABLE ${eventsTableHelper.tableName} ADD COLUMN ${eventsTableHelper.colQrCode} TEXT;
A42: ,[NfcSerial] as nfcSerial | B42: TEXT | C42: =SUBSTITUTE(TRIM(RIGHT(SUBSTITUTE(A42," ",REPT(" ",100)),100)),",","") -> nfcSerial | D42: ="this."&C42 & "," -> this.nfcSerial, | E42: ="final " & VLOOKUP(B42,Sheet2!$A$1:$B$4,2,FALSE) & " " & C42 & ";" -> final String nfcSerial; | F42: =UPPER(MID(C42,1,1)) & MID(C42,2,9999) -> NfcSerial | G42: ="col"&F42 -> colNfcSerial | H42: ="final String "&G42&"= '"&C42&"';" -> final String colNfcSerial= 'nfcSerial'; | I42: ="$"&G42&" "&B42&"," -> $colNfcSerial TEXT, | J42: ="ALTER TABLE ${"&$J$1&".tableName} ADD COLUMN ${"&$J$1&"."&G42&"} "&B42&";" -> ALTER TABLE ${eventsTableHelper.tableName} ADD COLUMN ${eventsTableHelper.colNfcSerial} TEXT;
A43: ,[PointType] as pointType | B43: INT | C43: =SUBSTITUTE(TRIM(RIGHT(SUBSTITUTE(A43," ",REPT(" ",100)),100)),",","") -> pointType | D43: ="this."&C43 & "," -> this.pointType, | E43: ="final " & VLOOKUP(B43,Sheet2!$A$1:$B$4,2,FALSE) & " " & C43 & ";" -> final int pointType; | F43: =UPPER(MID(C43,1,1)) & MID(C43,2,9999) -> PointType | G43: ="col"&F43 -> colPointType | H43: ="final String "&G43&"= '"&C43&"';" -> final String colPointType= 'pointType'; | I43: ="$"&G43&" "&B43&"," -> $colPointType INT, | J43: ="ALTER TABLE ${"&$J$1&".tableName} ADD COLUMN ${"&$J$1&"."&G43&"} "&B43&";" -> ALTER TABLE ${eventsTableHelper.tableName} ADD COLUMN ${eventsTableHelper.colPointType} INT;
A44: ,[CheckInOutType] as checkInOutType | B44: INT | C44: =SUBSTITUTE(TRIM(RIGHT(SUBSTITUTE(A44," ",REPT(" ",100)),100)),",","") -> checkInOutType | D44: ="this."&C44 & "," -> this.checkInOutType, | E44: ="final " & VLOOKUP(B44,Sheet2!$A$1:$B$4,2,FALSE) & " " & C44 & ";" -> final int checkInOutType; | F44: =UPPER(MID(C44,1,1)) & MID(C44,2,9999) -> CheckInOutType | G44: ="col"&F44 -> colCheckInOutType | H44: ="final String "&G44&"= '"&C44&"';" -> final String colCheckInOutType= 'checkInOutType'; | I44: ="$"&G44&" "&B44&"," -> $colCheckInOutType INT, | J44: ="ALTER TABLE ${"&$J$1&".tableName} ADD COLUMN ${"&$J$1&"."&G44&"} "&B44&";" -> ALTER TABLE ${eventsTableHelper.tableName} ADD COLUMN ${eventsTableHelper.colCheckInOutType} INT;
A45: ,[RiskFactor] as riskFactor | B45: NUM | C45: =SUBSTITUTE(TRIM(RIGHT(SUBSTITUTE(A45," ",REPT(" ",100)),100)),",","") -> riskFactor | D45: ="this."&C45 & "," -> this.riskFactor, | E45: ="final " & VLOOKUP(B45,Sheet2!$A$1:$B$4,2,FALSE) & " " & C45 & ";" -> final num riskFactor; | F45: =UPPER(MID(C45,1,1)) & MID(C45,2,9999) -> RiskFactor | G45: ="col"&F45 -> colRiskFactor | H45: ="final String "&G45&"= '"&C45&"';" -> final String colRiskFactor= 'riskFactor'; | I45: ="$"&G45&" "&B45&"," -> $colRiskFactor NUM, | J45: ="ALTER TABLE ${"&$J$1&".tableName} ADD COLUMN ${"&$J$1&"."&G45&"} "&B45&";" -> ALTER TABLE ${eventsTableHelper.tableName} ADD COLUMN ${eventsTableHelper.colRiskFactor} NUM;
A46: ,[Lat] as lat | B46: NUM | C46: =SUBSTITUTE(TRIM(RIGHT(SUBSTITUTE(A46," ",REPT(" ",100)),100)),",","") -> lat | D46: ="this."&C46 & "," -> this.lat, | E46: ="final " & VLOOKUP(B46,Sheet2!$A$1:$B$4,2,FALSE) & " " & C46 & ";" -> final num lat; | F46: =UPPER(MID(C46,1,1)) & MID(C46,2,9999) -> Lat | G46: ="col"&F46 -> colLat | H46: ="final String "&G46&"= '"&C46&"';" -> final String colLat= 'lat'; | I46: ="$"&G46&" "&B46&"," -> $colLat NUM, | J46: ="ALTER TABLE ${"&$J$1&".tableName} ADD COLUMN ${"&$J$1&"."&G46&"} "&B46&";" -> ALTER TABLE ${eventsTableHelper.tableName} ADD COLUMN ${eventsTableHelper.colLat} NUM;
A47: ,[Lon] as lon | B47: NUM | C47: =SUBSTITUTE(TRIM(RIGHT(SUBSTITUTE(A47," ",REPT(" ",100)),100)),",","") -> lon | D47: ="this."&C47 & "," -> this.lon, | E47: ="final " & VLOOKUP(B47,Sheet2!$A$1:$B$4,2,FALSE) & " " & C47 & ";" -> final num lon; | F47: =UPPER(MID(C47,1,1)) & MID(C47,2,9999) -> Lon | G47: ="col"&F47 -> colLon | H47: ="final String "&G47&"= '"&C47&"';" -> final String colLon= 'lon'; | I47: ="$"&G47&" "&B47&"," -> $colLon NUM, | J47: ="ALTER TABLE ${"&$J$1&".tableName} ADD COLUMN ${"&$J$1&"."&G47&"} "&B47&";" -> ALTER TABLE ${eventsTableHelper.tableName} ADD COLUMN ${eventsTableHelper.colLon} NUM;
...

Sheet Sheet2
A1: TEXT | B1: String
A2: TEXT NOT NULL | B2: String
A3: INT | B3: int
A4: NUM | B4: num
